{
 "cells": [
  {
   "cell_type": "markdown",
   "id": "b96bc22e",
   "metadata": {},
   "source": [
    "# Python Exceptions\n",
    "An exception is an unexpected event that occurs during program execution. For example,\n",
    "\n",
    "divide_by_zero = 7 / 0\n",
    "\n",
    "The above code causes an exception as it is not possible to divide a number by 0.\n",
    "\n",
    "Let's learn about Python Exceptions in detail."
   ]
  },
  {
   "cell_type": "markdown",
   "id": "0c907d3c",
   "metadata": {},
   "source": [
    "### Python Logical Errors (Exceptions):\n",
    "Errors that occur at runtime (after passing the syntax test) are called exceptions or logical errors.\n",
    "\n",
    "For instance, they occur when we\n",
    "\n",
    "try to open a file(for reading) that does not exist (FileNotFoundError)\n",
    "\n",
    "try to divide a number by zero (ZeroDivisionError)\n",
    "\n",
    "try to import a module that does not exist (ImportError) and so on.\n",
    "\n",
    "Whenever these types of runtime errors occur, Python creates an exception object.\n",
    "\n",
    "If not handled properly, it prints a traceback to that error along with some details about why that error occurred."
   ]
  },
  {
   "cell_type": "code",
   "execution_count": 1,
   "id": "c56742d3",
   "metadata": {},
   "outputs": [
    {
     "ename": "ZeroDivisionError",
     "evalue": "division by zero",
     "output_type": "error",
     "traceback": [
      "\u001b[1;31m---------------------------------------------------------------------------\u001b[0m",
      "\u001b[1;31mZeroDivisionError\u001b[0m                         Traceback (most recent call last)",
      "Cell \u001b[1;32mIn[1], line 1\u001b[0m\n\u001b[1;32m----> 1\u001b[0m a\u001b[38;5;241m=\u001b[39m\u001b[38;5;241m7\u001b[39m\u001b[38;5;241m/\u001b[39m\u001b[38;5;241m0\u001b[39m\n\u001b[0;32m      2\u001b[0m \u001b[38;5;28mprint\u001b[39m(a)\n",
      "\u001b[1;31mZeroDivisionError\u001b[0m: division by zero"
     ]
    }
   ],
   "source": [
    "a=7/0\n",
    "print(a)"
   ]
  },
  {
   "cell_type": "markdown",
   "id": "02435e61",
   "metadata": {},
   "source": [
    "### Python Built-in Exceptions\n",
    "Illegal operations can raise exceptions. There are plenty of built-in exceptions in Python that are raised when corresponding errors occur.\n",
    "\n",
    "We can view all the built-in exceptions using the built-in local() function as follows:"
   ]
  },
  {
   "cell_type": "code",
   "execution_count": 2,
   "id": "e093b045",
   "metadata": {},
   "outputs": [
    {
     "name": "stdout",
     "output_type": "stream",
     "text": [
      "['ArithmeticError', 'AssertionError', 'AttributeError', 'BaseException', 'BaseExceptionGroup', 'BlockingIOError', 'BrokenPipeError', 'BufferError', 'BytesWarning', 'ChildProcessError', 'ConnectionAbortedError', 'ConnectionError', 'ConnectionRefusedError', 'ConnectionResetError', 'DeprecationWarning', 'EOFError', 'Ellipsis', 'EncodingWarning', 'EnvironmentError', 'Exception', 'ExceptionGroup', 'False', 'FileExistsError', 'FileNotFoundError', 'FloatingPointError', 'FutureWarning', 'GeneratorExit', 'IOError', 'ImportError', 'ImportWarning', 'IndentationError', 'IndexError', 'InterruptedError', 'IsADirectoryError', 'KeyError', 'KeyboardInterrupt', 'LookupError', 'MemoryError', 'ModuleNotFoundError', 'NameError', 'None', 'NotADirectoryError', 'NotImplemented', 'NotImplementedError', 'OSError', 'OverflowError', 'PendingDeprecationWarning', 'PermissionError', 'ProcessLookupError', 'RecursionError', 'ReferenceError', 'ResourceWarning', 'RuntimeError', 'RuntimeWarning', 'StopAsyncIteration', 'StopIteration', 'SyntaxError', 'SyntaxWarning', 'SystemError', 'SystemExit', 'TabError', 'TimeoutError', 'True', 'TypeError', 'UnboundLocalError', 'UnicodeDecodeError', 'UnicodeEncodeError', 'UnicodeError', 'UnicodeTranslateError', 'UnicodeWarning', 'UserWarning', 'ValueError', 'Warning', 'WindowsError', 'ZeroDivisionError', '__IPYTHON__', '__build_class__', '__debug__', '__doc__', '__import__', '__loader__', '__name__', '__package__', '__spec__', 'abs', 'aiter', 'all', 'anext', 'any', 'ascii', 'bin', 'bool', 'breakpoint', 'bytearray', 'bytes', 'callable', 'chr', 'classmethod', 'compile', 'complex', 'copyright', 'credits', 'delattr', 'dict', 'dir', 'display', 'divmod', 'enumerate', 'eval', 'exec', 'execfile', 'filter', 'float', 'format', 'frozenset', 'get_ipython', 'getattr', 'globals', 'hasattr', 'hash', 'help', 'hex', 'id', 'input', 'int', 'isinstance', 'issubclass', 'iter', 'len', 'license', 'list', 'locals', 'map', 'max', 'memoryview', 'min', 'next', 'object', 'oct', 'open', 'ord', 'pow', 'print', 'property', 'range', 'repr', 'reversed', 'round', 'runfile', 'set', 'setattr', 'slice', 'sorted', 'staticmethod', 'str', 'sum', 'super', 'tuple', 'type', 'vars', 'zip']\n"
     ]
    }
   ],
   "source": [
    "print(dir(locals()['__builtins__']))"
   ]
  },
  {
   "cell_type": "markdown",
   "id": "c2066c14",
   "metadata": {},
   "source": [
    "### Python Error and Exception\n",
    "Errors represent conditions such as compilation error, syntax error, error in the logical part of the code, library incompatibility, infinite recursion, etc.\n",
    "\n",
    "Errors are usually beyond the control of the programmer and we should not try to handle errors.\n",
    "\n",
    "Exceptions can be caught and handled by the program.\n",
    "\n",
    "Now we know about exceptions, we will learn about handling exceptions in the next tutorial."
   ]
  },
  {
   "cell_type": "code",
   "execution_count": null,
   "id": "98b40544",
   "metadata": {},
   "outputs": [],
   "source": []
  }
 ],
 "metadata": {
  "kernelspec": {
   "display_name": "Python 3 (ipykernel)",
   "language": "python",
   "name": "python3"
  },
  "language_info": {
   "codemirror_mode": {
    "name": "ipython",
    "version": 3
   },
   "file_extension": ".py",
   "mimetype": "text/x-python",
   "name": "python",
   "nbconvert_exporter": "python",
   "pygments_lexer": "ipython3",
   "version": "3.11.5"
  }
 },
 "nbformat": 4,
 "nbformat_minor": 5
}
